Workbook

Sheet Projets
A1: PROJETS (reconstruit à partir d'Accords_consolides — fusion sans doublon)
A2: Code_Projet | B2: Intitule_Projet | C2: Annee_Collecte | D2: Categorie | E2: Envergure | F2: Secteur_Activite_1 | G2: Secteur_Activite_2 | H2: Secteur_Activite_3 | I2: Sous_Secteur | J2: Tutelle | K2: Agence_Exécution | L2: Contexte_Justification | M2: Problematique | N2: Objectif_Global | O2: Objectifs_Specifiques | P2: Principaux_Resultats | Q2: Composantes_Projet | R2: Activites_Principales | S2: Beneficiaires_Directs | T2: Beneficiaires_Indirects | U2: Departement | V2: Commune | W2: Arrondissement | X2: Village_Quartier | Y2: Coordonnees_GPS | Z2: Date_Approbation | AA2: Date_Signature | AB2: Date_Vigueur | AC2: Date_Demarrage | AD2: Date_Cloture | AE2: Duree_Initiale_Mois | AF2: Est_Proroge | AG2: Date_Prorogation | AH2: Motif_Prorogation | AI2: Nouvelle_Date_Cloture | AJ2: Nb_Prorogations | AK2: Cout_Total_USD | AL2: Devise | AM2: Taux_Change | AN2: Cout_Total_FCFA | AO2: Milliards_FCFA | AP2: Contrepartie_BN_USD | AQ2: Contrepartie_BN_FCFA | AR2: Don_Attendu_FCFA | AS2: Pret_Attendu_FCFA | AT2: PPP_Attendu_FCFA | AU2: Contribution_Benef_FCFA | AV2: Gap_Financement | AW2: Pourcentage_Acquis | AX2: Source_Financement | AY2: APD_Oui_Non | AZ2: Type_Financement | BA2: Contributeur | BB2: Sigle_Partenaire | BC2: Type_Contributeur | BD2: Co_Partenaire_1 | BE2: Co_Partenaire_2 | BF2: Co_Partenaire_3 | BG2: Co_Partenaire_4 | BH2: Co_Partenaire_5 | BI2: Co_Partenaire_6 | BJ2: Co_Partenaire_7 | BK2: Statut_Projet | BL2: Secteur_PAG | BM2: Pilier_PAG | BN2: Axe_PAG | BO2: ODD | BP2: Cible_ODD | BQ2: Pilier_National | BR2: Resp_Banque_Nom | BS2: Resp_Banque_Tel1 | BT2: Resp_Banque_Tel2 | BU2: Resp_Banque_Email | BV2: Coord_Projet_Nom | BW2: Coord_Projet_Tel1 | BX2: Coord_Projet_Tel2 | BY2: Coord_Projet_Email | BZ2: RAF_Nom | CA2: RAF_Tel1 | CB2: RAF_Tel2 | CC2: RAF_Email | CD2: Resp_SE_Nom | CE2: Resp_SE_Tel1 | CF2: Resp_SE_Tel2 | CG2: Resp_SE_Email | CH2: Niveau_Maturite | CI2: Etude_Faisabilite | CJ2: Etude_Environnementale | CK2: Plan_Affaires | CL2: Dossier_Technique | CM2: Categorie_Env | CN2: Theme_Genre | CO2: Theme_Inclusion | CP2: Theme_Climat | CQ2: Theme_Emploi_Jeunes | CR2: Risques_Identifies | CS2: Mesures_Attenuation | CT2: Niveau_Risque | CU2: Date_Soumission | CV2: Avis_Technique | CW2: Avis_DGFD | CX2: Avis_Ministere | CY2: Decision_Comite | CZ2: Date_Validation | DA2: Note_Conceptuelle | DB2: Cadre_Logique | DC2: Budget_Detaille | DD2: Cartographie | DE2: Lettre_Demande | DF2: Zone_intervention | DG2: Modalite_Intervention | DH2: Nature_Financement | DI2: Instrument_Financement | DJ2: Source_Verifiable | DK2: Montant_Devise_Origine
A3: P-0001-BIDC-2011 | B3: Projet d'électrification rurale de soixante sept (67) localités en République du Bénin | F3: ÉNERGIE | N3: Accroître le taux d'accès à l'électricité en milieu rural en raccordant 67 localités isolées au réseau électrique de la SBEE pour stimuler l'économie locale et améliorer les services sociaux de base. | U3: Alibori, Borgou, Collines, Zou, Couffo, Mono, Atlantique, Ouémé, Plateau | V3: Banikoara, Gogounou, Kandi, Malanville, Segbana, Bembérèké, Kalalé, N'Dali, Nikki, Parakou, Pérére, Sinendé, Tchaourou, Bantè, Dassa-Zoumé, Glazoué, Ouèssè, Savalou, Savè, Abomey, Agbangnizoun, Bohicon, Covè, Djidja, Ouinhi, Za-Kpota, Zagnanado, Zogbodomey, Aplahoué, Djakotomey, Dogbo, Klouékanmè, Lalo, Toviklin, Athiémé, Bopa, Comè, Grand-Popo, Houéyogbé, Lokossa, Abomey-Calavi, Allada, Kpomassè, Ouidah, Sô-Ava, Toffo, Tori-Bossito, Zè, Adjarra, Adjohoun, Agégué, Akpro-Missérété, Avrankou, Bonou, Dangbo, Porto-Novo, Sèmè-Podji, Adja-Ouéré, Ifangni, Kétou, Pobè, Sakété | Z3: 40511 | AA3: 40548 | AD3: 43100 | AL3: EUR | AN3: 10000000000 | AR3: 0 | AS3: 10000000000 | BA3: Banque d’Investissement et de Développement de la CEDEAO | BB3: BIDC | BC3: MULTILATERAUX | DF3: ALIBORI (BANIKOARA, GOGOUNOU, KANDI, MALANVILLE, SEGBANA) ; BORGOU (BEMBÉRÈKÉ, KALALÉ, N'DALI, NIKKI, PARAKOU, PÉRÉRE, SINENDÉ, TCHAOUROU) ; COLLINES (BANTÈ, DASSA-ZOUMÉ, GLAZOUÉ, OUÈSSÈ, SAVALOU, SAVÈ) ; ZOU (ABOMEY, AGBANGNIZOUN, BOHICON, COVÈ, DJIDJA, OUINHI, ZA-KPOTA, ZAGNANADO, ZOGBODOMEY) ; COUFFO (APLAHOUÉ, DJAKOTOMEY, DOGBO, KLOUÉKANMÈ, LALO, TOVIKLIN) ; MONO (ATHIÉMÉ, BOPA, COMÈ, GRAND-POPO, HOUÉYOGBÉ, LOKOSSA) ; ATLANTIQUE (ABOMEY-CALAVI, ALLADA, KPOMASSÈ, OUIDAH, SÔ-AVA, TOFFO, TORI-BOSSITO, ZÈ) ; OUÉMÉ (ADJARRA, ADJOHOUN, AGÉGUÉ, AKPRO-MISSÉRÉTÉ, AVRANKOU, BONOU, DANGBO, PORTO-NOVO, SÈMÈ-PODJI) ; PLATEAU (ADJA-OUÉRÉ, IFANGNI, KÉTOU, POBÈ, SAKÉTÉ). | DG3: Projet d'investissement | DH3: Prêt | DI3: Prêt non concessionnel | DJ3: https://evaluation.gouv.bj | DK3: 20000000
A4: P-0002-BOAD-2011 | B4: Projet de construction de la ligne d'interconnexion électrique 161 KV Bembèrèkè-Kandi-Malanville | F4: ÉNERGIE | N4: Sécuriser et accroître l'approvisionnement en énergie électrique des localités septentrionales du Bénin et faciliter l'interconnexion avec le réseau du Niger grâce à la construction d'une ligne de transport haute tension. | U4: Borgou, Alibori | V4: Bembérèké, Gogounou, Kandi, Malanville | W4: Bembérèké Centre, Gogounou Centre, Bagou, Gounarou, Kandi I, Kandi II, Donwari, Sam, Malanville Centre, Guéné, Garou | Z4: 40527 | AA4: 40565 | AD4: 42735 | AL4: XOF | AN4: 20000000000 | AR4: 0 | AS4: 20000000000 | BA4: Banque Ouest Africaine de Développement | BB4: BOAD | BC4: MULTILATERAUX | DF4: BORGOU (BEMBÉRÈKÉ(BEMBÉRÈKÉ CENTRE)) ; ALIBORI (GOGOUNOU(GOGOUNOU CENTRE, BAGOU, GOUNAROU), KANDI(KANDI I, KANDI II, DONWARI, SAM), MALANVILLE(MALANVILLE CENTRE, GUÉNÉ, GAROU)). | DG4: Projet d'investissement | DH4: Prêt | DI4: Prêt non concessionnel | DJ4: https://boad.org | DK4: 20000000000
A5: P-0003-OFID/OPEP-2011 | B5: Projet de construction de la route Kandi-Ségbana-Frontière du Nigeria | F5: INFRASTRUCTURES ROUTIERES ET TRANSPORT | N5: Améliorer le niveau de service de l'axe routier reliant Kandi à la frontière du Nigeria afin de réduire les coûts de transport, désenclaver les zones agricoles traversées et dynamiser le commerce transfrontalier. | U5: Alibori | V5: Kandi, Ségbana | W5: Kandi I, Ségbana Centre, Liboussou, Lougou, Sokotindji | X5: Samia | Z5: 40528 | AA5: 40556 | AD5: 43281 | AL5: EUR | AN5: 5225000000 | AR5: 0 | AS5: 5225000000 | BA5: Fonds de l’OPEP pour le Développement International | BB5: OFID/OPEP | BC5: MULTILATERAUX | DF5: ALIBORI (KANDI(KANDI I), SÉGBANA(SÉGBANA CENTRE, LIBOUSSOU, LOUGOU, SOKOTINDJI(SAMIA))). | DG5: Projet d'investissement | DH5: Prêt | DI5: Prêt concessionnel | DJ5: https://documentation-anbenin.org | DK5: 11000000
A6: P-0004-FND-2011 | B6: Projet de Développement de l'Accès à l'Energie Moderne par la Biomasse | F6: ÉNERGIE | N6: Promouvoir l'utilisation de technologies énergétiques durables basées sur la biomasse, réduire la pression sur les ressources forestières à travers la diffusion de foyers améliorés et renforcer les capacités des acteurs de la filière bois-énergie. | U6: Collines, Zou, Borgou | V6: Savalou, Dassa-Zoumé, Glazoué, Ouèssè, Djidja, Tchaourou | Z6: 40522 | AA6: 40574 | AD6: 43100 | AL6: EUR | AN6: 983935500 | AR6: 983935500 | AS6: 0 | BA6: Fonds Nordique de Développement | BB6: FND | BC6: MULTILATERAUX | DF6: COLLINES (SAVALOU, DASSA-ZOUMÉ, GLAZOUÉ, OUÈSSÈ) ; ZOU (DJIDJA, SAVALOU) ; BORGOU (TCHAOUROU). | DG6: Projet d'investissement | DH6: Don | DI6: Don | DJ6: https://direction-energie.gouv.bj | DK6: 1500000
A7: P-0005-BID-2011 | B7: Assistance technique au profit du Ministère de la Prospective, du Développement, de l'Evaluation des Politiques Publiques et de la Coordination de l'Action Gouvernementale | F7: GOUVERNANCE | N7: Renforcer les capacités institutionnelles et techniques du ministère dans la formulation des politiques de développement, la planification stratégique à long terme et l'évaluation d'impact des politiques publiques. | U7: Littoral | V7: Cotonou | Z7: 40532 | AA7: 40588 | AD7: 42004 | AL7: DI | AN7: 150000000 | AR7: 150000000 | AS7: 0 | BA7: Banque Islamique de Développement | BB7: BID | BC7: MULTILATERAUX | DF7: LITTORAL (COTONOU). | DG7: Assistance technique / Renforcement institutionnel | DH7: Don | DI7: Assistance technique | DJ7: https://gouv.bj | DK7: 200000
A8: P-0006-BM-2011 | B8: Financement supplémentaire au sixième Crédit d'Appui à la Réduction de la Pauvreté (PRSC-6) | F8: GOUVERNANCE | N8: Soutenir la mise en œuvre de la stratégie de croissance pour la réduction de la pauvreté en améliorant la gestion des finances publiques, l'efficacité de la dépense sociale et le climat des investissements. | U8: National | Z8: 40631 | AA8: 40660 | AD8: 41274 | AL8: DTS | AN8: 11000000000 | AR8: 11000000000 | AS8: 0 | BA8: Banque mondiale | BB8: BM | BC8: MULTILATERAUX | DF8: NATIONAL | DG8: Appui budgétaire sectoriel | DH8: Don | DI8: Don | DJ8: https://banquemondiale.org | DK8: 14000000
A9: P-0007-BOAD-2011 | B9: Projet d'Aménagement et de Bitumage de la route Ouidah-Allada et de la bretelle Pahou-Tori. | F9: INFRASTRUCTURES ROUTIERES ET TRANSPORT | N9: Assurer la liaison routière moderne entre les communes de Ouidah et d'Allada afin de faciliter la circulation des personnes et des biens, de désenclaver les zones de production agricole et de soutenir l'axe touristique de l'Atlantique. | U9: Atlantique | V9: Ouidah, Tori-Bossito, Allada | W9: Ouidah I, Ouidah II, Savi, Tori-Cada, Tori-Gbégamey, Tori-Bossito Centre, Allada Centre, Lon-Agonmey, Hinvi | Z9: 40527 | AA9: 40681 | AD9: 42735 | AL9: XOF | AN9: 5320000000 | AR9: 0 | AS9: 5320000000 | BA9: Banque Ouest Africaine de Développement | BB9: BOAD | BC9: MULTILATERAUX | DF9: ATLANTIQUE (OUIDAH(OUIDAH I, OUIDAH II, SAVI), TORI-BOSSITO(TORI-CADA, TORI-GBÉGAMEY, TORI-BOSSITO CENTRE), ALLADA(ALLADA CENTRE, LON-AGONMEY, HINVI)). | DG9: Projet d'investissement | DH9: Prêt | DI9: Prêt non concessionnel | DJ9: https://boad.org | DK9: 5320000000
A10: P-0008-BM-2011 | B10: Projet de Productivité Agricole en Afrique de l'Ouest (PPAAO) | F10: AGRICULTURE | N10: Générer et diffuser des technologies agricoles améliorées dans les filières prioritaires du Bénin, tout en renforçant les systèmes de recherche agricole et la coopération scientifique régionale en Afrique de l'Ouest. | U10: Borgou, Atlantique, Ouémé | V10: Bembérèké, Allada, Adjohoun, Bonou, Dangbo | W10: Ina, Niaouli | Z10: 40626 | AA10: 40701 | AD10: 42735 | AL10: DTS | AN10: 8400000000 | AR10: 8400000000 | AS10: 0 | BA10: Banque mondiale | BB10: BM | BC10: MULTILATERAUX | DF10: BORGOU (BEMBÉRÈKÉ(INA)) ; ATLANTIQUE (ALLADA(NIAOULI)) ; OUÉMÉ (ADJOHOUN, BONOU, DANGBO). | DG10: Projet d'investissement | DH10: Don | DI10: Don | DJ10: https://banquemondiale.org | DK10: 11000000
A11: P-0009-BM-2011 | B11: Projet d'Appui à la Diversification Agricole (PADA) | F11: AGRICULTURE | N11: Restaurer et améliorer la productivité et la compétitivité des filières agricoles cibles (notamment le riz, le maïs, l'anacarde et l'ananas) pour accroître les revenus des petits producteurs et sécuriser la souveraineté alimentaire. | U11: Ouémé, Zou, Collines, Atlantique | V11: Dangbo, Adjohoun, Bonou, Abomey, Bohicon, Zakpota, Dassa-Zoumé, Savalou, Abomey-Calavi, Zè | Z11: 40626 | AA11: 40701 | AD11: 42794 | AL11: DTS | EUR | AN11: 23000000000 | AR11: 7500000000 | AS11: 15500000000 | BA11: Banque mondiale | BB11: BM | BC11: MULTILATERAUX | DF11: OUÉMÉ (DANGBO, ADJOHOUN, BONOU) ; ZOU (ABOMEY, BOHICON, ZAKPOTA) ; COLLINES (DASSA-ZOUMÉ, SAVALOU) ; ATLANTIQUE (ABOMEY-CALAVI, ZÈ). | DG11: Projet d'investissement | DH11: Don | Prêt | DI11: Fonds fiduciaire (Trust Fund) | Prêt concessionnel | DJ11: https://banquemondiale.org | DK11: 35000000
A12: P-0010-BM-2011 | B12: Projet d'Appui à la Gestion des Aires Protégées | F12: CADRE DE VIE | N12: Consolider et étendre les investissements destinés à la structuration des chaînes de valeur agricoles afin d'amplifier l'accès aux marchés des groupements de producteurs et d'améliorer la commercialisation des produits locaux. | U12: Ouémé, Zou, Collines, Atlantique | V12: Dangbo, Adjohoun, Bonou, Abomey, Bohicon, Zakpota, Dassa-Zoumé, Savalou, Abomey-Calavi, Zè | Z12: 40631 | AA12: 40701 | AD12: 43646 | AL12: DTS | EUR | AN12: 3450000000 | AR12: 3450000000 | AS12: 0 | BA12: Banque mondiale | BB12: BM | BC12: MULTILATERAUX | DF12: OUÉMÉ (DANGBO, ADJOHOUN, BONOU) ; ZOU (ABOMEY, BOHICON, ZAKPOTA) ; COLLINES (DASSA-ZOUMÉ, SAVALOU) ; ATLANTIQUE (ABOMEY-CALAVI, ZÈ). | DG12: Projet d'investissement | DH12: Don | DI12: Don | Fonds fiduciaire (Trust Fund) | DJ12: https://banquemondiale.org | DK12: 5200000
A13: P-0011-BM-2011 | B13: Projet d'Urgence de Gestion Environnementale en Milieu Urbain | F13: CADRE DE VIE | N13: Améliorer la gestion durable des écosystèmes des parcs nationaux du W et de la Pendjari, renforcer la conservation de la biodiversité et impliquer les communautés locales dans la gouvernance des ressources naturelles. | U13: Atacora, Alibori | V13: Tanguiéta, Kérou, Banikoara | W13: Tanguiéta Centre, Banikoara Centre | Z13: 40631 | AA13: 40701 | AD13: 43496 | AL13: DTS | AN13: 25000000000 | AR13: 0 | AS13: 25000000000 | BA13: Banque mondiale | BB13: BM | BC13: MULTILATERAUX | DF13: ATACORA (TANGUIÉTA(TANGUIÉTA CENTRE), KÉROU) ; ALIBORI (BANIKOARA(BANIKOARA CENTRE)). | DG13: Projet d'investissement | DH13: Prêt | DI13: Prêt concessionnel | DJ13: https://banquemondiale.org | DK13: 31600000
A14: P-0012-BM-2011 | B14: Projet de Nutrition Communautaire | F14: SANTÉ | N14: Réduire la vulnérabilité des populations du Grand Nokoué face aux inondations récurrentes, améliorer les infrastructures d'assainissement pluvial et optimiser la gestion des déchets solides ménagers. | U14: Littoral, Atlantique, Ouémé | V14: Cotonou, Abomey-Calavi, Ouidah, Porto-Novo, Sèmè-Podji | W14: Du 1er au 13ème, Godomey, Abomey-Calavi Centre, Akassato, Du 1er au 5ème | Z14: 40687 | AA14: 40724 | AD14: 42735 | AL14: EUR | AN14: 1398890500 | AR14: 1398890500 | AS14: 0 | BA14: Banque mondiale | BB14: BM | BC14: MULTILATERAUX | DF14: LITTORAL (COTONOU(DU 1ER AU 13ÈME)) ; ATLANTIQUE (ABOMEY-CALAVI(GODOMEY, ABOMEY-CALAVI CENTRE, AKASSATO), OUIDAH) ; OUÉMÉ (PORTO-NOVO(DU 1ER AU 5ÈME), SÈMÈ-PODJI). | DG14: Projet d'investissement | DH14: Don | DI14: Don | DJ14: https://evaluation.gouv.bj | DK14: 2797781
A15: P-0013-BOAD-2011 | B15: Projet de pavage de rues et d'assainissement dans la Commune d'Abomey-Calavi | F15: CADRE DE VIE | N15: Moderniser la voirie urbaine des arrondissements centraux d'Abomey-Calavi par le pavage et la construction de collecteurs d'eaux pluviales afin d'améliorer les conditions de circulation et d'hygiène des populations. | U15: Atlantique | V15: Abomey-Calavi | W15: Abomey-Calavi Centre, Godomey, Akassato, Zinvié | Z15: 40688 | AA15: 40739 | AD15: 42735 | AL15: XOF | AN15: 6500000000 | AR15: 0 | AS15: 6500000000 | BA15: Banque Ouest Africaine de Développement | BB15: BOAD | BC15: MULTILATERAUX | DF15: ATLANTIQUE (ABOMEY-CALAVI(ABOMEY-CALAVI CENTRE, GODOMEY, AKASSATO, ZINVIÉ)). | DG15: Projet d'investissement | DH15: Prêt | DI15: Prêt non concessionnel | DJ15: https://boad.org | DK15: 6500000000
A16: P-0014-BM-2011 | B16: Projet d'appui institutionnel au profit du Ministère du Développement, de l'Analyse Economique et de la Prospective et de la Primature | F16: GOUVERNANCE | N16: Renforcer les compétences techniques des cadres de l'administration centrale pour améliorer le suivi des indicateurs macroéconomiques, l'évaluation des politiques sectorielles et la coordination gouvernementale. | U16: Littoral | V16: Cotonou | Z16: 40709 | AA16: 40781 | AD16: 42369 | AL16: EUR | AN16: 240875000 | AR16: 240875000 | AS16: 0 | BA16: Banque mondiale | BB16: BM | BC16: MULTILATERAUX | DF16: LITTORAL (COTONOU). | DG16: Assistance technique / Renforcement institutionnel | DH16: Don | DI16: Appui institutionnel | DJ16: https://gouv.bj | DK16: 481750
A17: P-0015-BOAD-2011 | B17: Avance de fonds pour le financement des études de faisabilité du projet de développement d'infrastructures socio-économiques et de sécurité alimentaire dans le bassin du Niger | F17: AGRICULTURE | N17: Réaliser les études techniques, environnementales et sociales préalables requises pour concevoir des aménagements hydro-agricoles et de stockage visant la sécurité alimentaire dans les communes du bassin du Niger. | U17: Alibori, Borgou, Atacora, Donga | V17: Banikoara, Karimama, Malanville, Bembérèké, Kalalé, Ndali, Nikki, Sinendé, Kérou, Kouandé, Péhunco, Tanguiéta, Djougou | Z17: 40688 | AA17: 40794 | AD17: 41820 | AL17: XOF | AN17: 380000000 | AR17: 0 | AS17: 380000000 | BA17: Banque Ouest Africaine de Développement | BB17: BOAD | BC17: MULTILATERAUX | DF17: ALIBORI (BANIKOARA, KARIMAMA, MALANVILLE) ; BORGOU (BEMBÉRÈKÉ, KALALÉ, NDALI, NIKKI, SINENDÉ) ; ATACORA (KÉROU, KOUANDÉ, PÉHUNCO, TANGUIÉTA) ; DONGA (DJOUGOU). | DG17: Étude / Préparation | DH17: Prêt | DI17: Avance de préparation de projet | DJ17: https://boad.org | DK17: 380000000
A18: P-0016-FKDEA-2011 | B18: Financement des micro et petites entreprises agricoles au Bénin. | F18: AGRICULTURE | N18: Faciliter l'accès aux crédits de campagne et d'équipement pour les petits exploitants et groupements agricoles à travers le refinancement des systèmes financiers décentralisés. | U18: National | Z18: 40724 | AA18: 40808 | AD18: 43465 | AL18: EUR | AN18: 2500000000 | AR18: 2500000000 | AS18: 0 | BA18: Fonds Koweïtien pour le Développement Économique Arabe | BB18: FKDEA | BC18: BILATERAUX | DF18: NATIONAL | DG18: Projet d'investissement | DH18: Don | DI18: Don | DJ18: https://evaluation.gouv.bj | DK18: 5000000
A19: P-0017-BM-2011 | B19: Projet Régional de Facilitation du Commerce-Phase II | F19: INDUSTRIE ET COMMERCE | N19: Réduire les barrières commerciales le long des corridors d'échanges, moderniser les procédures douanières aux frontières et simplifier le transit des marchandises pour stimuler l'intégration économique régionale. | U19: Littoral, Atlantique, Zou, Collines, Borgou, Alibori, Ouémé | V19: Cotonou, Allada, Bohicon, Savalou, Tchaourou, Parakou, Kandi, Malanville, Porto-Novo | W19: Malanville Centre | Z19: 40715 | AA19: 40856 | AD19: 43008 | AL19: DTS | AN19: 3750000000 | AR19: 3750000000 | AS19: 0 | BA19: Banque mondiale | BB19: BM | BC19: MULTILATERAUX | DF19: LITTORAL (COTONOU) ; ATLANTIQUE (ALLADA) ; ZOU (BOHICON) ; COLLINES (SAVALOU, TCHAOUROU) ; BORGOU (PARAKOU) ; ALIBORI (KANDI, MALANVILLE(MALANVILLE CENTRE)) ; OUÉMÉ (PORTO-NOVO). | DG19: Projet d'investissement | DH19: Don | DI19: Don | DJ19: https://banquemondiale.org | DK19: 4800000
A20: P-0018-BM-2011 | B20: Projet d'Appui à la Promotion Apicole (PAPA) | F20: AGRICULTURE | N20: Soutenir les filières horticoles et maraîchères en fournissant des intrants de qualité, en structurant les coopératives et en développant de petites infrastructures de marché dans les zones de production. | U20: Ouémé, Plateau, Zou, Collines | V20: Adjohoun, Bonou, Dangbo, Pobè, Kétou, Abomey, Bohicon, Zakpota, Dassa-Zoumé, Savalou | Z20: 40673 | AA20: 40856 | AD20: 42735 | AL20: EUR | AN20: 1282658000 | AR20: 1282658000 | AS20: 0 | BA20: Banque mondiale | BB20: BM | BC20: MULTILATERAUX | DF20: OUÉMÉ (ADJOHOUN, BONOU, DANGBO) ; PLATEAU (POBÈ, KÉTOU) ; ZOU (ABOMEY, BOHICON, ZAKPOTA) ; COLLINES (DASSA-ZOUMÉ, SAVALOU). | DG20: Projet d'investissement | DH20: Don | DI20: Don | DJ20: https://banquemondiale.org | DK20: 2565316
A21: P-0019-BM-2011 | B21: Projet de Développement de l'Accès à l'Energie Moderne (DAEM) | F21: ÉNERGIE | N21: Élargir l'accès aux services électriques et aux solutions de cuisson propres dans les zones rurales et périurbaines à travers des mécanismes de financement adaptés et la promotion des énergies renouvelables. | U21: Collines, Zou, Borgou, Donga | V21: Dassa-Zoumé, Savalou, Bohicon, Djidja, Tchaourou, Parakou, Djougou | Z21: 40717 | AA21: 40856 | AD21: 43100 | AL21: EUR | AN21: 1000000000 | AR21: 1000000000 | AS21: 0 | BA21: Banque mondiale | BB21: BM | BC21: MULTILATERAUX | DF21: COLLINES (DASSA-ZOUMÉ, SAVALOU) ; ZOU (BOHICON, DJIDJA) ; BORGOU (TCHAOUROU, PARAKOU) ; DONGA (DJOUGOU). | DG21: Projet d'investissement | DH21: Don | DI21: Fonds fiduciaire (Trust Fund) | DJ21: https://direction-energie.gouv.bj | DK21: 2000000
A22: P-0020-Allemagne-2011 | B22: Augmentation cofinancement pots communs de l'alimentation en eau potable | F22: EAU ET ASSAINISSEMENT | N22: Accroître la desserte en eau potable en milieu rural et semi-urbain dans l'Atacora et la Donga par la réhabilitation et l'extension de systèmes d'adduction d'eau villageoise. | U22: Atacora, Donga | V22: Natitingou, Boukoumbé, Toucountouna, Tanguiéta, Djougou, Copargo, Ouaké | Z22: 40861 | AA22: 40871 | AD22: 42369 | AL22: EUR | AN22: 13776000000 | AR22: 13776000000 | AS22: 0 | BA22: Allemagne | BB22: Allemagne | BC22: BILATERAUX | DF22: ATACORA (NATITINGOU, BOUKOUMBÉ, TOUCOUNTOUNA, TANGUIÉTA) ; DONGA (DJOUGOU, COPARGO, OUAKÉ). | DG22: Projet d'investissement | DH22: Don | DI22: Cofinancement | DJ22: https://evaluation.gouv.bj | DK22: 21000000
A23: P-0021-BAD-2011 | B23: Projet de réhabilitation de la route Lomé-Cotonou et de facilitation du transport sur le corridor Abidjan-Lagos-phase I | F23: INFRASTRUCTURES ROUTIERES ET TRANSPORT | N23: Consolider les investissements d'aménagement routier sur le corridor côtier, incluant les travaux de protection de l'infrastructure contre l'érosion marine sur les segments critiques. | U23: Mono, Atlantique, Littoral | V23: Grand-Popo, Ouidah, Cotonou | W23: Agoué | X23: Agoué, Hillacondji | Z23: 40837 | AA23: 40879 | AD23: 43830 | AL23: UC | AN23: 52330000000 | AR23: 24520000000 | AS23: 27810000000 | BA23: Banque Africaine de Développement | BB23: BAD | BC23: MULTILATERAUX | DF23: MONO (GRAND-POPO(AGOUÉ(AGOUÉ, HILLACONDJI))) ; ATLANTIQUE (OUIDAH) ; LITTORAL (COTONOU). | DG23: Projet d'investissement | DH23: Don | Prêt | DI23: Don | Prêt concessionnel | DJ23: https://documentation-anbenin.org | DK23: 73140000
A24: P-0022-Allemagne-2011 | B24: Financement de la phase II du Fonds d'Appui au Développement des Communes (FADEC) | F24: DÉCENTRALISATION | N24: Assurer le transfert effectif de ressources financières aux collectivités locales pour le financement de leurs infrastructures sociocommunautaires (écoles, dispensaires, marchés). | U24: National | Z24: 40855 | AA24: 40892 | AD24: 42004 | AL24: EUR | AN24: 5903613000 | AR24: 5903613000 | AS24: 0 | BA24: Allemagne | BB24: Allemagne | BC24: BILATERAUX | DF24: NATIONAL | DG24: Fonds commun | DH24: Don | DI24: Don | DJ24: https://evaluation.gouv.bj | DK24: 9000000
A25: P-0023-BM-2011 | B25: Septième don d'appui à la réduction de la pauvreté (PRSG-7) | F25: GOUVERNANCE | N25: Appuyer les réformes macroéconomiques sectorielles de l'État visant la transparence budgétaire, la stabilité fiscale et le financement adéquat des services sociaux essentiels. | U25: National | Z25: 40631 | AA25: 40898 | AD25: 41274 | AL25: EUR | AN25: 15000000000 | AR25: 15000000000 | AS25: 0 | BA25: Banque mondiale | BB25: BM | BC25: MULTILATERAUX | DF25: NATIONAL | DG25: Projet d'investissement | DH25: Don | DI25: Don | DJ25: https://banquemondiale.org | DK25: 30000000
A26: P-0024-BOAD-2011 | B26: Projet de pavage et d'assainissement de rues dans les villes de Kétou, Tchaourou et Savè | F26: CADRE DE VIE | N26: Améliorer le cadre de vie urbain dans les trois communes bénéficiaires par le revêtement des voies secondaires et la construction d'ouvrages de drainage des eaux pluviales. | U26: Plateau, Borgou, Collines | V26: Kétou, Tchaourou, Savè | Z26: 40681 | AA26: 40908 | AD26: 42185 | AL26: XOF | AN26: 7000000000 | AR26: 0 | AS26: 7000000000 | BA26: Banque Ouest Africaine de Développement | BB26: BOAD | BC26: MULTILATERAUX | DF26: PLATEAU (KÉTOU) ; BORGOU (TCHAOUROU) ; COLLINES (SAVÈ). | DG26: Projet d'investissement | DH26: Prêt | DI26: Prêt non concessionnel | DJ26: https://boad.org | DK26: 7000000000
A27: P-0003-FSD-2012 | B27: Projet de construction de la route Kandi-Ségbana-Frontière du Nigeria | F27: INFRASTRUCTURES ROUTIERES ET TRANSPORT | N27: Cofinancer les travaux de terrassement et de bitumage de l'axe routier reliant Kandi à la frontière nigériane pour soutenir le transit sous-régional des marchandises. | U27: Alibori | V27: Kandi, Ségbana | W27: Ségbana Centre | X27: Samia | Z27: 40994 | AA27: 41043 | AD27: 43830 | AL27: SAR | AN27: 8000000000 | AR27: 0 | AS27: 8000000000 | BA27: Fonds Saoudien de Développement | BB27: FSD | BC27: BILATERAUX | DF27: ALIBORI (KANDI, SÉGBANA(SÉGBANA CENTRE(SAMIA))). | DG27: Projet d'investissement | DH27: Prêt | DI27: Prêt concessionnel | DJ27: https://documentation-anbenin.org | DK27: 60000000
A28: P-0025-BADEA-2012 | B28: Projet de pont sur le fleuve "Mono" | F28: INFRASTRUCTURES ROUTIERES ET TRANSPORT | N28: Faciliter les échanges transfrontaliers et sécuriser la liaison permanente entre le Bénin et le Togo par la construction d'un ouvrage de franchissement moderne sur le fleuve Mono à Athiémé. | U28: Mono | V28: Athiémé | W28: Athiémé Centre | Z28: 40865 | AA28: 40926 | AD28: 43646 | AL28: EUR | AN28: 5200000000 | AR28: 0 | AS28: 5200000000 | BA28: Banque Arabe pour le Développement Économique en Afrique | BB28: BADEA | BC28: MULTILATERAUX | DF28: MONO (ATHIÉMÉ(ATHIÉMÉ CENTRE)). | DG28: Projet d'investissement | DH28: Prêt | DI28: Prêt concessionnel | DJ28: https://documentation-anbenin.org | DK28: 10400000
A29: P-0026-Danemark-2012 | B29: Contribution au Fonds d'Appui au Développement des Communes (FADEC) | F29: DÉCENTRALISATION | N29: Contribuer à la réduction de la pauvreté et à l'amélioration durable des conditions de vie des populations par le renforcement de la décentralisation et le financement des investissements des collectivités territoriales, afin d'améliorer la fourniture des services publics locaux. | U29: National | Z29: 40941 | AA29: 41011 | AD29: 43465 | AL29: DKK | AN29: 3520000000 | AR29: 3520000000 | AS29: 0 | BA29: Danemark | BB29: Danemark | BC29: BILATERAUX | DF29: NATIONAL | DG29: Fonds commun | DH29: Don | DI29: Don | DJ29: Programme d'appui danois à la décentralisation (Danida) et FADeC - Ministère de la Décentralisation ; documentation du FADeC | DK29: 40000000
A30: P-0027-Danemark-2012 | B30: Programme d'appui au sous-secteur de l'enseignement primaire au Bénin | F30: ÉDUCATION | N30: Renforcer les capacités financières locales des communes à travers des transferts budgétaires dédiés au développement d'infrastructures de base sous maîtrise d'ouvrage communale. | U30: National | Z30: 40984 | AA30: 41044 | AD30: 42916 | AL30: DKK | AN30: 11060000000 | AR30: 11060000000 | AS30: 0 | BA30: Danemark | BB30: Danemark | BC30: BILATERAUX | DF30: NATIONAL | DG30: Programme d'investissement | DH30: Don | DI30: Don | DJ30: https://evaluation.gouv.bj | DK30: 125000000
A31: P-0028-Danemark-2012 | B31: Programme d'appui au sous-secteur du transport rural au Bénin | F31: INFRASTRUCTURES ROUTIERES ET TRANSPORT | N31: Améliorer la qualité et l'accès à l'éducation primaire publique en milieu rural, notamment dans les départements du Nord, à travers la construction de salles de classe et la formation des enseignants. | U31: Alibori, Atacora, Borgou, Donga | Z31: 40984 | AA31: 41082 | AD31: 43830 | AL31: DKK | AN31: 8850000000 | AR31: 8850000000 | AS31: 0 | BA31: Danemark | BB31: Danemark | BC31: BILATERAUX | DF31: ALIBORI ; ATACORA ; BORGOU ; DONGA. | DG31: Programme d'investissement | DH31: Don | DI31: Don | DJ31: https://evaluation.gouv.bj | DK31: 100000000
A32: P-0028-PAYS-BAS-2012 | B32: Programme d'appui au sous-secteur du transport rural au Bénin | F32: INFRASTRUCTURES ROUTIERES ET TRANSPORT | N32: Co-investir dans l'extension des linéaires de pistes de desserte rurale réhabilitées dans les bassins de production agricole pour optimiser les circuits de commercialisation. | U32: Alibori, Atacora, Borgou, Donga | Z32: 41193 | AA32: 41201 | AD32: 43100 | AL32: EUR | AN32: 3481277936 | AR32: 3481277936 | AS32: 0 | BA32: Royaume des Pays-Bas / Coopération néerlandaise | BB32: PAYS-BAS | BC32: BILATERAUX | DF32: ALIBORI ; ATACORA ; BORGOU ; DONGA. | DG32: Programme d'investissement | DH32: Don | DI32: Don | DJ32: evaluation.gouv.bj | DK32: 5307635.2
A33: P-0029-BOAD-2012 | B33: Etudes de faisabilité technique et d'impact environnemental et social du projet d'aménagement et de bitumage de la route Lalo-Agbangnizoun-Abomey-Djidja-Agouna-Tchetti-Doumè-Ottola-Bantè | F33: INFRASTRUCTURES ROUTIERES ET TRANSPORT | N33: Réaliser les études techniques détaillées et d'ingénierie nécessaires pour la future construction et le bitumage de cet axe routier transversal reliant les départements du Couffo, du Zou et des Collines. | U33: Couffo, Zou, Collines | V33: Lalo, Agbangnizoun, Abomey, Djidja, Savalou | W33: Agouna, Tchetti) ; Savè(Dovè, Obola | Z33: 40988 | AA33: 41054 | AD33: 42369 | AL33: XOF | AN33: 480000000 | AR33: 0 | AS33: 480000000 | BA33: Banque Ouest Africaine de Développement | BB33: BOAD | BC33: MULTILATERAUX | DF33: COUFFO (LALO) ; ZOU (AGBANGNIZOUN, ABOMEY, DJIDJA) ; COLLINES (SAVALOU(AGOUNA, TCHETTI) ; SAVÈ(DOVÈ, OBOLA)). | DG33: Étude / Préparation | DH33: Prêt | DI33: Prêt non concessionnel | DJ33: https://boad.org | DK33: 480000000
A34: P-0030-AFD-2012 | B34: Programme d'Appui à la Santé Maternelle et Infantile (PASMI) | F34: SANTÉ | N34: Réduire la mortalité maternelle et néonatale dans les zones cibles en améliorant la qualité des soins obstétricaux d'urgence et en équipant les maternités des hôpitaux de zone. | U34: Ouémé, Plateau, Zou, Collines | V34: Porto-Novo, Akpro-Missérété, Avrankou, Pobè, Adja-Ouéré, Kétou, Abomey, Bohicon, Dassa-Zoumé, Savalou | Z34: 41044 | AA34: 41079 | AD34: 43281 | AL34: EUR | AN34: 6559570000 | AR34: 6559570000 | AS34: 0 | BA34: Agence Française de Développement | BB34: AFD | BC34: BILATERAUX | DF34: OUÉMÉ (PORTO-NOVO, AKPRO-MISSÉRÉTÉ, AVRANKOU) ; PLATEAU (POBÈ, ADJA-OUÉRÉ, KÉTOU) ; ZOU (ABOMEY, BOHICON) ; COLLINES (DASSA-ZOUMÉ, SAVALOU). | DG34: Programme d'investissement | DH34: Don | DI34: Don | DJ34: https://evaluation.gouv.bj | DK34: 10000000
A35: P-0031-BM-2012 | B35: Projet de services décentralisées conduits par les communautés (PSDCC) | F35: DÉCENTRALISATION | N35: Améliorer l'accès des communautés vulnérables à des infrastructures socio-économiques de base gérées de façon participative et renforcer le système national de filets sociaux. | U35: National | Z35: 41025 | AA35: 41087 | AD35: 43465 | AL35: DTS | AN35: 23000000000 | AR35: 0 | AS35: 23000000000 | BA35: Banque mondiale | BB35: BM | BC35: MULTILATERAUX | DF35: NATIONAL | DG35: Projet d'investissement | DH35: Prêt | DI35: Prêt concessionnel | DJ35: https://banquemondiale.org | DK35: 29600000
A36: P-0032-BIDC-2012 | B36: Projet d'équipement et de réhabilitation de formations sanitaires | F36: SANTÉ | N36: Moderniser le plateau technique de plusieurs hôpitaux de référence au Bénin par l'acquisition de matériels d'imagerie, de laboratoire et de réanimation médicale. | U36: Littoral, Borgou, Ouémé, Atacora | V36: Cotonou, Parakou, Porto-Novo, Natitingou | Z36: 41093 | AA36: 41116 | AD36: 43100 | AL36: EUR | AN36: 5000000000 | AR36: 0 | AS36: 5000000000 | BA36: Banque d’Investissement et de Développement de la CEDEAO | BB36: BIDC | BC36: MULTILATERAUX | DF36: LITTORAL (COTONOU) ; BORGOU (PARAKOU) ; OUÉMÉ (PORTO-NOVO) ; ATACORA (NATITINGOU). | DG36: Projet d'investissement | DH36: Prêt | DI36: Prêt non concessionnel | DJ36: evaluation.gouv.bj | DK36: 10000000
A37: P-0033-BOAD-2012 | B37: Projet d'aménagement de la route des pêches | F37: INFRASTRUCTURES ROUTIERES ET TRANSPORT | N37: Développer le potentiel touristique et halieutique de la zone côtière par la construction d'une route bitumée reliant Cotonou à Ouidah le long du littoral. | U37: Littoral, Atlantique | V37: Cotonou, Abomey-Calavi | W37: Fidjrossè, Godomey(Togbin)) ; Ouidah(Avlékété, Houakpè-Daho | Z37: 41054 | AA37: 41120 | AD37: 42735 | AL37: XOF | AN37: 12000000000 | AR37: 0 | AS37: 12000000000 | BA37: Banque Ouest Africaine de Développement | BB37: BOAD | BC37: MULTILATERAUX | DF37: LITTORAL (COTONOU(FIDJROSSÈ)) ; ATLANTIQUE (ABOMEY-CALAVI(GODOMEY(TOGBIN)) ; OUIDAH(AVLÉKÉTÉ, HOUAKPÈ-DAHO)). | DG37: Projet d'investissement | DH37: Prêt | DI37: Prêt non concessionnel | DJ37: boad.org | DK37: 12000000000
A38: P-0034-Chine-2012 | B38: Financement de divers projets | F38: GOUVERNANCE | N38: Appuyer l'État béninois dans la réalisation d'infrastructures administratives et d'équipements socioculturels définis dans le cadre des accords bilatéraux de coopération. | U38: Littoral, Atlantique | V38: Cotonou, Abomey-Calavi | Z38: 41142 | AA38: 41170 | AD38: 43100 | AL38: CNY | AN38: 10790000000 | AR38: 0 | AS38: 10790000000 | BA38: Chine | BB38: Chine | BC38: BILATERAUX | DF38: LITTORAL (COTONOU) ; ATLANTIQUE (ABOMEY-CALAVI). | DG38: Projet d'investissement | DH38: Prêt | DI38: Prêt | DJ38: https://gouv.bj | DK38: 141000000
A39: P-0035-EXIMBANK INDE-2012 | B39: Projet d'installation d'une usine de montage de tracteurs et d'équipements agricoles à Ouidah | F39: AGRICULTURE | N39: Promouvoir la mécanisation de l'agriculture béninoise par la mise en place d'une unité industrielle de montage de tracteurs et de machines agricoles afin de réduire la pénibilité du travail de terre. | U39: Atlantique | V39: Ouidah | W39: Pahou | Z39: 41064 | AA39: 41144 | AD39: 42735 | AL39: EUR | AN39: 7500000000 | AR39: 0 | AS39: 7500000000 | BA39: Export-Import Bank of India | BB39: EXIMBANK INDE | BC39: BILATERAUX | DF39: ATLANTIQUE (OUIDAH(PAHOU)). | DG39: Projet d'investissement | DH39: Prêt | DI39: Prêt concessionnel | DJ39: documentation-anbenin.org | DK39: 15000000
A40: P-0036-BM-2012 | B40: Première phase du Programme Régional Ouest Africain d'Infrastructures de Communication-Projet Bénin | F40: NUMÉRIQUE | N40: Accroître la connectivité numérique internationale du Bénin et réduire les coûts des services de télécommunications à large bande grâce à l'extension du réseau de fibre optique. | U40: Littoral, Atlantique, Ouémé | V40: Cotonou, Abomey-Calavi, Porto-Novo | Z40: 41102 | AA40: 41156 | AD40: 43646 | AL40: DTS | AN40: 17500000000 | AR40: 0 | AS40: 17500000000 | BA40: Banque mondiale | BB40: BM | BC40: MULTILATERAUX | DF40: LITTORAL (COTONOU) ; ATLANTIQUE (ABOMEY-CALAVI) ; OUÉMÉ (PORTO-NOVO). | DG40: Projet d'investissement | DH40: Prêt | DI40: Prêt concessionnel | DJ40: banquemondiale.org | DK40: 23200000
...

Sheet Localisation
A1: N° | B1: Département | C1: Commune | D1: Arrondissement | E1: Village ou quartier de Ville
A2: 1 | B2: ALIBORI | C2: KANDI | D2: ANGARADEBOU | E2: 1. Akoïtchaou
A3: 2 | B3: ALIBORI | C3: KANDI | D3: ANGARADEBOU | E3: 2. Alfakoara
A4: 3 | B4: ALIBORI | C4: KANDI | D4: ANGARADEBOU | E4: 3. Angaradébou
A5: 4 | B5: ALIBORI | C5: KANDI | D5: ANGARADEBOU | E5: 4. Dogban
A6: 5 | B6: ALIBORI | C6: KANDI | D6: ANGARADEBOU | E6: 5. Fafa
A7: 6 | B7: ALIBORI | C7: KANDI | D7: ANGARADEBOU | E7: 6. Fouet
A8: 7 | B8: ALIBORI | C8: KANDI | D8: ANGARADEBOU | E8: 7. Kabagbèdè
A9: 8 | B9: ALIBORI | C9: KANDI | D9: ANGARADEBOU | E9: 8. Kpalolo
A10: 9 | B10: ALIBORI | C10: KANDI | D10: ANGARADEBOU | E10: 9. Sékalé
A11: 10 | B11: ALIBORI | C11: KANDI | D11: ANGARADEBOU | E11: 10. Sondo
A12: 11 | B12: ALIBORI | C12: KANDI | D12: ANGARADEBOU | E12: 11. Soundou
A13: 12 | B13: ALIBORI | C13: KANDI | D13: ANGARADEBOU | E13: 12. Tchoka
... A5291: 5320 | B5291: ZOU | C5291: ZOGBODOMEY | D5291: ZOUKOU | E5291: 6. Zoukou

Sheet Paramètres
A1: SECTEUR | B1: SOUS_SECTEUR | C1: PARTENAIRE | D1: TYPE_FINANC | E1: TYPE_PARTEN | F1: SECTEUR_PAG | G1: PILIER_PAG | H1: AXE_PAG | I1: STATUT_PROJET | J1: DEPARTEMENTS | K1: basePart | L1: type_engagem | M1: annee | N1: trimestre | O1: ODD | P1: COMMUNES | Q1: DEVISE | R1: MODALITE_INTERV | S1: NATURE_FINANC
A2: ÉNERGIE | B2: Production d’électricité | C2: AFD | D2: Don | E2: Bilatéral | F2: Transformation économique | G2: PILIER 1 | H2: AXE 1 | I2: En approbation | J2: Alibori | K2: MAEP | L2: Projet d'investissement | M2: 2011 | N2: trim1 | O2: ODD 1 | P2: Cotonou | Q2: XOF - Franc CFA BCEAO | R2: Aide humanitaire | S2: Don
A3: ÉNERGIE | B3: Transport d’énergie | C3: ALLEMAGNE | D3: Prêt concessionnel | E3: Multilatéral | F3: Capital humain | G3: PILIER 2 | H3: AXE 2 | I3: En cours | J3: Atacora | K3: MS | L3: Programme sectoriel | M3: 2012 | N3: trim2 | O3: ODD 2 | P3: Porto-Novo | Q3: EUR - Euro | R3: Appui budgétaire général | S3: Prêt
A4: ÉNERGIE | B4: Distribution d’électricité | C4: BAD | D4: Prêt non-concessionnel | E4: Fonds fiduciaire | F4: Gouvernance | G4: PILIER 3 | H4: AXE 3 | I4: Achevé | J4: Atlantique | K4: MENFP | L4: Appui budgétaire général | M4: 2013 | N4: trim3 | O4: ODD 3 | P4: Parakou | Q4: USD - Dollar américain | R4: Appui budgétaire sectoriel | S4: Don | Prêt
A5: ÉNERGIE | B5: Électrification rurale | C5: BADEA | D5: PPP | E5: ONG internationale | F5: Croissance inclusive | H5: AXE 4 | I5: En retard | J5: Borgou | K5: MEF | L5: Assistance technique | M5: 2014 | N5: trim4 | O5: ODD 4 | P5: Abomey-Calavi | Q5: GBP - Livre sterling | R5: Assistance technique / Renforcement institutionnel
A6: ÉNERGIE | B6: Électrification urbaine | C6: BANQUE ATLANTIQUE BENIN | D6: Subvention | E6: Agence spécialisée | F6: Infrastructures | H6: AXE 5 | I6: Abandonné | J6: Collines | K6: DGFD | L6: Étude / Préparation | M6: 2015 | O6: ODD 5 | P6: Bohicon | Q6: CAD - Dollar canadien | R6: Fonds commun
A7: ÉNERGIE | B7: Énergies renouvelables | C7: BCI | D7: Garantie souveraine | E7: Institution financière | F7: Numérique | H7: AXE 6 | I7: Suspendu | J7: Couffo | K7: MTP | L7: Appui budgétaire ciblé | M7: 2016 | O7: ODD 6 | P7: Natitingou | Q7: CHF - Franc suisse | R7: Gestion de la dette
A8: ÉNERGIE | B8: Énergie solaire | C8: BEI | D8: Appui budgétaire | E8: Secteur privé | F8: Environnement | H8: AXE 7 | J8: Donga | K8: MCVDD | M8: 2017 | O8: ODD 7 | P8: Lokossa | Q8: CNY - Yuan chinois | R8: Ligne de crédit
A9: ÉNERGIE | B9: Biomasse et biogaz | C9: BELGIQUE | D9: Co-financement | E9: Marché financier | J9: Littoral | K9: MERS | M9: 2018 | O9: ODD 8 | P9: Ouidah | Q9: JPY - Yen japonais | R9: PforR
A10: ÉNERGIE | B10: Efficacité énergétique | C10: BGFI | D10: Emprunt obligataire | J10: Mono | K10: MDN | M10: 2019 | O10: ODD 9 | P10: Djougou | Q10: NGN - Naira nigérian | R10: Programme d'investissement
A11: ÉNERGIE | B11: Éclairage public | C11: BID | J11: Ouémé | K11: MISP | M11: 2020 | O11: ODD 10 | P11: Kandi | Q11: GHS - Cedi ghanéen | R11: Projet d'investissement
A12: ÉNERGIE | B12: Mines | C12: BIDC | J12: Plateau | K12: MTCA | M12: 2021 | O12: ODD 11 | P12: Abomey | Q12: ZAR - Rand sud-africain | R12: Étude / Préparation
A13: AGRICULTURE | B13: Production végétale | C13: BM | J13: Zou | K13: MEN | M13: 2022 | O13: ODD 12 | P13: Dogbo | Q13: AUD - Dollar australien
A14: AGRICULTURE | B14: Riziculture | C14: BNP-PARIBAS | K14: MSP | M14: 2023 | O14: ODD 13 | P14: Dassa-Zoumè | Q14: NZD - Dollar néo-zélandais
A15: AGRICULTURE | B15: Maraîchage | C15: BOA-BENIN | K15: MJLDH | M15: 2024 | O15: ODD 14 | P15: Savalou | Q15: SEK - Couronne suédoise
A16: AGRICULTURE | B16: Cultures de rente | C16: BOAD | K16: MERPMEDER | M16: 2025 | O16: ODD 15 | P16: Bassila | Q16: NOK - Couronne norvégienne
A17: AGRICULTURE | B17: Irrigation et maîtrise de l’eau | C17: BRESIL | K17: Présidence | M17: 2026 | O17: ODD 17 | P17: Malanville | Q17: AED - Dirham des Émirats arabes unis
A18: AGRICULTURE | B18: Mécanisation agricole | C18: CANADA | K18: Autre | M18: 2027 | P18: Nikki | Q18: SAR - Riyal saoudien
A19: AGRICULTURE | B19: Stockage et conservation | C19: CHINE | M19: 2028 | P19: Tchaourou | Q19: QAR - Riyal qatari
A20: AGRICULTURE | B20: Transformation agroalimentaire | C20: COOPÉRATION SUISSE | M20: 2029 | P20: Pobè | Q20: KWD - Dinar koweïtien
A21: AGRICULTURE | B21: Recherche et innovation agricoles | C21: DEUTSCHE BANK | M21: 2030 | P21: Sakété | Q21: BHD - Dinar bahreïni
A22: AGRICULTURE | B22: Conseil agricole | C22: DIAMOND BANK | M22: 2031 | P22: Adjohoun | Q22: OMR - Rial omanais
A23: AGRICULTURE | B23: Élevage | C23: EUROBOND | M23: 2032 | P23: Avrankou | Q23: INR - Roupie indienne
A24: AGRICULTURE | B24: Pêche et aquaculture | C24: EUROBOND_21 | M24: 2033 | P24: Dangbo | Q24: KRW - Won sud-coréen
A25: AGRICULTURE | B25: Sécurité alimentaire | C25: FIDA | M25: 2034 | P25: Akpro-Missérété | Q25: SGD - Dollar de Singapour
A26: CADRE DE VIE | B26: Urbanisme | C26: FKDEA | M26: 2035 | P26: Sèmè-Kpodji | Q26: HKD - Dollar de Hong Kong
A27: CADRE DE VIE | B27: Aménagement urbain | C27: FMI | M27: 2036 | P27: Aguégués | Q27: TRY - Livre turque
A28: CADRE DE VIE | B28: Habitat et logements sociaux | C28: FND | P28: Sotouboua | Q28: RUB - Rouble russe
A29: CADRE DE VIE | B29: Voirie urbaine | C29: FONROCHE | P29: Glazoué | Q29: MAD - Dirham marocain
A30: CADRE DE VIE | B30: Assainissement pluvial | C30: FSD | P30: Savé | Q30: TND - Dinar tunisien
A31: CADRE DE VIE | B31: Gestion des déchets solides | C31: JAPON | P31: Bantè | Q31: DZD - Dinar algérien
A32: CADRE DE VIE | B32: Espaces verts et embellissement | C32: KBC ET RABOBANK | P32: Ouèssè | Q32: EGP - Livre égyptienne
A33: CADRE DE VIE | B33: Gestion des marchés et équipements urbains | C33: KFW | P33: Zagnanado | Q33: XAF - Franc CFA BEAC
A34: CADRE DE VIE | B34: Environnement et changements climatiques | C34: LUXDEV | P34: Zangnanado
A35: CADRE DE VIE | B35: Gestion des ressources naturelles | C35: LUXEMBOURG | P35: Covè
A36: CADRE DE VIE | B36: Lutte contre les inondations | C36: Marché financier | P36: Djidja
A37: CADRE DE VIE | B37: Lutte contre l’érosion côtière | C37: Mfin | P37: Zogbodomey
A38: CULTURE ET TOURISME | B38: Patrimoine culturel | C38: NATIXIS | P38: Lalo
A39: CULTURE ET TOURISME | B39: Musées et sites historiques | C39: NORVEGE | P39: Aplahoué
A40: CULTURE ET TOURISME | B40: Arts et spectacles | C40: ODDO-BHF | P40: Djakotomey
...

Sheet Suivi_Trimestriel
A1: Code_Projet | B1: Annee_Suivi | C1: Trimestre | D1: TEF_Trim | E1: Montant_Decaisse_USD | F1: Montant_Decaisse_FCFA | G1: TEP_Trim | H1: Activites_Realisees | I1: TEF_Cumule | J1: TEP_Cumule | K1: Difficultes_Rencontrees | L1: Approches_Solution | M1: Recommandations | N1: Date_Saisie
A2: PRJ-2025-001 | B2: 2025 | C2: trim1 | D2: 0.12 | E2: 450000 | F2: =IFERROR(E2*610,"") -> 274500000 | G2: 0.15 | H2: Études techniques lancées, recrutement en cours | I2: =IFERROR(SUMIF(A:A,A2,D:D),"") -> 0.12 | J2: =IFERROR(AVERAGEIF(A:A,A2,G:G),"") -> 0.15 | K2: Retards dans les appels d'offres | L2: Renforcement équipe passation des marchés | M2: Accélérer procédures DAO Q2 | N2: =TODAY() -> 46238
F3: =IFERROR(E3*VLOOKUP(TODAY(),Paramètres!$A:$B,2,1),"") | I3: =IFERROR(SUMIF(A:A,A3,D:D),"") -> 0 | J3: =IFERROR(AVERAGEIF(A:A,A3,G:G),"") | N3: =TODAY() -> 46238
F4: =IFERROR(E4*VLOOKUP(TODAY(),Paramètres!$A:$B,2,1),"") | I4: =IFERROR(SUMIF(A:A,A4,D:D),"") -> 0 | J4: =IFERROR(AVERAGEIF(A:A,A4,G:G),"") | N4: =TODAY() -> 46238
F5: =IFERROR(E5*VLOOKUP(TODAY(),Paramètres!$A:$B,2,1),"") | I5: =IFERROR(SUMIF(A:A,A5,D:D),"") -> 0 | J5: =IFERROR(AVERAGEIF(A:A,A5,G:G),"") | N5: =TODAY() -> 46238
F6: =IFERROR(E6*VLOOKUP(TODAY(),Paramètres!$A:$B,2,1),"") | I6: =IFERROR(SUMIF(A:A,A6,D:D),"") -> 0 | J6: =IFERROR(AVERAGEIF(A:A,A6,G:G),"") | N6: =TODAY() -> 46238
F7: =IFERROR(E7*VLOOKUP(TODAY(),Paramètres!$A:$B,2,1),"") | I7: =IFERROR(SUMIF(A:A,A7,D:D),"") -> 0 | J7: =IFERROR(AVERAGEIF(A:A,A7,G:G),"") | N7: =TODAY() -> 46238
F8: =IFERROR(E8*VLOOKUP(TODAY(),Paramètres!$A:$B,2,1),"") | I8: =IFERROR(SUMIF(A:A,A8,D:D),"") -> 0 | J8: =IFERROR(AVERAGEIF(A:A,A8,G:G),"") | N8: =TODAY() -> 46238
F9: =IFERROR(E9*VLOOKUP(TODAY(),Paramètres!$A:$B,2,1),"") | I9: =IFERROR(SUMIF(A:A,A9,D:D),"") -> 0 | J9: =IFERROR(AVERAGEIF(A:A,A9,G:G),"") | N9: =TODAY() -> 46238
F10: =IFERROR(E10*VLOOKUP(TODAY(),Paramètres!$A:$B,2,1),"") | I10: =IFERROR(SUMIF(A:A,A10,D:D),"") -> 0 | J10: =IFERROR(AVERAGEIF(A:A,A10,G:G),"") | N10: =TODAY() -> 46238
F11: =IFERROR(E11*VLOOKUP(TODAY(),Paramètres!$A:$B,2,1),"") | I11: =IFERROR(SUMIF(A:A,A11,D:D),"") -> 0 | J11: =IFERROR(AVERAGEIF(A:A,A11,G:G),"") | N11: =TODAY() -> 46238
F12: =IFERROR(E12*VLOOKUP(TODAY(),Paramètres!$A:$B,2,1),"") | I12: =IFERROR(SUMIF(A:A,A12,D:D),"") -> 0 | J12: =IFERROR(AVERAGEIF(A:A,A12,G:G),"") | N12: =TODAY() -> 46238
F13: =IFERROR(E13*VLOOKUP(TODAY(),Paramètres!$A:$B,2,1),"") | I13: =IFERROR(SUMIF(A:A,A13,D:D),"") -> 0 | J13: =IFERROR(AVERAGEIF(A:A,A13,G:G),"") | N13: =TODAY() -> 46238
F14: =IFERROR(E14*VLOOKUP(TODAY(),Paramètres!$A:$B,2,1),"") | I14: =IFERROR(SUMIF(A:A,A14,D:D),"") -> 0 | J14: =IFERROR(AVERAGEIF(A:A,A14,G:G),"") | N14: =TODAY() -> 46238
... F101: =IFERROR(E101*VLOOKUP(TODAY(),Paramètres!$A:$B,2,1),"") | I101: =IFERROR(SUMIF(A:A,A101,D:D),"") -> 0 | J101: =IFERROR(AVERAGEIF(A:A,A101,G:G),"") | N101: =TODAY() -> 46238

Sheet Accords_consolides
B1: ACCORDS DE DÉVELOPPEMENT DU BÉNIN — BASE CONSOLIDÉE ENRICHIE
B2: Source : RCD + mabase | 865 accords | Généré le 30/07/2026
B3: Cette feuille enrichit la base RCD avec 11 colonnes issues de mabase, appariées par titre d'accord. La colonne Statut_Appariement indique la fiabilité de chaque appariement.
B5: TABLE DES ACCORDS CONSOLIDÉS ENRICHIS
B6: Code Projet | C6: Annee de signature | D6: Annee de cloture | E6: Modalité d'intervention | F6: Objet de l'accord | G6: Objectif général | H6: Source vérifiable | I6: Partenaire | J6: Sigle_Part | K6: Secteur principal | L6: Nature (Prêt/Don/Mixte) | M6: Montant_Pret_FCFA | N6: Montant_Don_FCFA | O6: Montant_Total_FCFA | P6: Devise | Q6: Montant total (devise) | R6: Instrument de financement | S6: Date de signature | T6: Date d'approbation | U6: Date de clôture | V6: Zone | W6: APD Oui/non | X6: TYPE DE FINANCEMENT | Y6: TYPE DE CONTRIBUTEUR | Z6: SOUS SECTEUR | AA6: AXE PAG | AB6: PILIER PAG | AC6: ODD | AD6: Cible_ODD | AE6: Pilier | AF6: STATUT (en cours, achevé, en approbation) | AG6: Objectifs spécifiques | AH6: Resultats attendues | AI6: Principales composantes | AJ6: Bénéficiaires directes | AK6: Population cible
B7: P-0001-BIDC-2011 | C7: 2011 | D7: =YEAR(U7) -> 2017 | E7: Projet d'investissement | F7: Projet d'électrification rurale de soixante sept (67) localités en République du Bénin | G7: Accroître le taux d'accès à l'électricité en milieu rural en raccordant 67 localités isolées au réseau électrique de la SBEE pour stimuler l'économie locale et améliorer les services sociaux de base. | H7: https://evaluation.gouv.bj | I7: Banque d’Investissement et de Développement de la CEDEAO | J7: BIDC | K7: ÉNERGIE | L7: Prêt | M7: 10000000000 | N7: 0 | O7: 10000000000 | P7: EUR | Q7: 20000000 | R7: Prêt non concessionnel | S7: 40548 | T7: 40511 | U7: 43100 | V7: ALIBORI (BANIKOARA, GOGOUNOU, KANDI, MALANVILLE, SEGBANA) ; BORGOU (BEMBÉRÈKÉ, KALALÉ, N'DALI, NIKKI, PARAKOU, PÉRÉRE, SINENDÉ, TCHAOUROU) ; COLLINES (BANTÈ, DASSA-ZOUMÉ, GLAZOUÉ, OUÈSSÈ, SAVALOU, SAVÈ) ; ZOU (ABOMEY, AGBANGNIZOUN, BOHICON, COVÈ, DJIDJA, OUINHI, ZA-KPOTA, ZAGNANADO, ZOGBODOMEY) ; COUFFO (APLAHOUÉ, DJAKOTOMEY, DOGBO, KLOUÉKANMÈ, LALO, TOVIKLIN) ; MONO (ATHIÉMÉ, BOPA, COMÈ, GRAND-POPO, HOUÉYOGBÉ, LOKOSSA) ; ATLANTIQUE (ABOMEY-CALAVI, ALLADA, KPOMASSÈ, OUIDAH, SÔ-AVA, TOFFO, TORI-BOSSITO, ZÈ) ; OUÉMÉ (ADJARRA, ADJOHOUN, AGÉGUÉ, AKPRO-MISSÉRÉTÉ, AVRANKOU, BONOU, DANGBO, PORTO-NOVO, SÈMÈ-PODJI) ; PLATEAU (ADJA-OUÉRÉ, IFANGNI, KÉTOU, POBÈ, SAKÉTÉ). | Y7: MULTILATERAUX | Z7: Production d’électricité
B8: P-0002-BOAD-2011 | C8: 2011 | D8: =YEAR(U8) -> 2016 | E8: Projet d'investissement | F8: Projet de construction de la ligne d'interconnexion électrique 161 KV Bembèrèkè-Kandi-Malanville | G8: Sécuriser et accroître l'approvisionnement en énergie électrique des localités septentrionales du Bénin et faciliter l'interconnexion avec le réseau du Niger grâce à la construction d'une ligne de transport haute tension. | H8: https://boad.org | I8: Banque Ouest Africaine de Développement | J8: BOAD | K8: ÉNERGIE | L8: Prêt | M8: 20000000000 | N8: 0 | O8: 20000000000 | P8: XOF | Q8: 20000000000 | R8: Prêt non concessionnel | S8: 40565 | T8: 40527 | U8: 42735 | V8: BORGOU (BEMBÉRÈKÉ(BEMBÉRÈKÉ CENTRE)) ; ALIBORI (GOGOUNOU(GOGOUNOU CENTRE, BAGOU, GOUNAROU), KANDI(KANDI I, KANDI II, DONWARI, SAM), MALANVILLE(MALANVILLE CENTRE, GUÉNÉ, GAROU)). | Y8: MULTILATERAUX
B9: P-0003-OFID/OPEP-2011 | C9: 2011 | D9: =YEAR(U9) -> 2018 | E9: Projet d'investissement | F9: Projet de construction de la route Kandi-Ségbana-Frontière du Nigeria | G9: Améliorer le niveau de service de l'axe routier reliant Kandi à la frontière du Nigeria afin de réduire les coûts de transport, désenclaver les zones agricoles traversées et dynamiser le commerce transfrontalier. | H9: https://documentation-anbenin.org | I9: Fonds de l’OPEP pour le Développement International | J9: OFID/OPEP | K9: INFRASTRUCTURES ROUTIERES ET TRANSPORT | L9: Prêt | M9: 5225000000 | N9: 0 | O9: 5225000000 | P9: EUR | Q9: 11000000 | R9: Prêt concessionnel | S9: 40556 | T9: 40528 | U9: 43281 | V9: ALIBORI (KANDI(KANDI I), SÉGBANA(SÉGBANA CENTRE, LIBOUSSOU, LOUGOU, SOKOTINDJI(SAMIA))). | Y9: MULTILATERAUX
B10: P-0004-FND-2011 | C10: 2011 | D10: =YEAR(U10) -> 2017 | E10: Projet d'investissement | F10: Projet de Développement de l'Accès à l'Energie Moderne par la Biomasse | G10: Promouvoir l'utilisation de technologies énergétiques durables basées sur la biomasse, réduire la pression sur les ressources forestières à travers la diffusion de foyers améliorés et renforcer les capacités des acteurs de la filière bois-énergie. | H10: https://direction-energie.gouv.bj | I10: Fonds Nordique de Développement | J10: FND | K10: ÉNERGIE | L10: Don | M10: 0 | N10: 983935500 | O10: 983935500 | P10: EUR | Q10: 1500000 | R10: Don | S10: 40574 | T10: 40522 | U10: 43100 | V10: COLLINES (SAVALOU, DASSA-ZOUMÉ, GLAZOUÉ, OUÈSSÈ) ; ZOU (DJIDJA, SAVALOU) ; BORGOU (TCHAOUROU). | Y10: MULTILATERAUX
B11: P-0005-BID-2011 | C11: 2011 | D11: =YEAR(U11) -> 2014 | E11: Assistance technique / Renforcement institutionnel | F11: Assistance technique au profit du Ministère de la Prospective, du Développement, de l'Evaluation des Politiques Publiques et de la Coordination de l'Action Gouvernementale | G11: Renforcer les capacités institutionnelles et techniques du ministère dans la formulation des politiques de développement, la planification stratégique à long terme et l'évaluation d'impact des politiques publiques. | H11: https://gouv.bj | I11: Banque Islamique de Développement | J11: BID | K11: GOUVERNANCE | L11: Don | M11: 0 | N11: 150000000 | O11: 150000000 | P11: DI | Q11: 200000 | R11: Assistance technique | S11: 40588 | T11: 40532 | U11: 42004 | V11: LITTORAL (COTONOU). | Y11: MULTILATERAUX
B12: P-0006-BM-2011 | C12: 2011 | D12: =YEAR(U12) -> 2012 | E12: Appui budgétaire sectoriel | F12: Financement supplémentaire au sixième Crédit d'Appui à la Réduction de la Pauvreté (PRSC-6) | G12: Soutenir la mise en œuvre de la stratégie de croissance pour la réduction de la pauvreté en améliorant la gestion des finances publiques, l'efficacité de la dépense sociale et le climat des investissements. | H12: https://banquemondiale.org | I12: Banque mondiale | J12: BM | K12: GOUVERNANCE | L12: Don | M12: 0 | N12: 11000000000 | O12: 11000000000 | P12: DTS | Q12: 14000000 | R12: Don | S12: 40660 | T12: 40631 | U12: 41274 | V12: NATIONAL | Y12: MULTILATERAUX
B13: P-0007-BOAD-2011 | C13: 2011 | D13: =YEAR(U13) -> 2016 | E13: Projet d'investissement | F13: Projet d'Aménagement et de Bitumage de la route Ouidah-Allada et de la bretelle Pahou-Tori. | G13: Assurer la liaison routière moderne entre les communes de Ouidah et d'Allada afin de faciliter la circulation des personnes et des biens, de désenclaver les zones de production agricole et de soutenir l'axe touristique de l'Atlantique. | H13: https://boad.org | I13: Banque Ouest Africaine de Développement | J13: BOAD | K13: INFRASTRUCTURES ROUTIERES ET TRANSPORT | L13: Prêt | M13: 5320000000 | N13: 0 | O13: 5320000000 | P13: XOF | Q13: 5320000000 | R13: Prêt non concessionnel | S13: 40681 | T13: 40527 | U13: 42735 | V13: ATLANTIQUE (OUIDAH(OUIDAH I, OUIDAH II, SAVI), TORI-BOSSITO(TORI-CADA, TORI-GBÉGAMEY, TORI-BOSSITO CENTRE), ALLADA(ALLADA CENTRE, LON-AGONMEY, HINVI)). | Y13: MULTILATERAUX
B14: P-0008-BM-2011 | C14: 2011 | D14: =YEAR(U14) -> 2016 | E14: Projet d'investissement | F14: Projet de Productivité Agricole en Afrique de l'Ouest (PPAAO) | G14: Générer et diffuser des technologies agricoles améliorées dans les filières prioritaires du Bénin, tout en renforçant les systèmes de recherche agricole et la coopération scientifique régionale en Afrique de l'Ouest. | H14: https://banquemondiale.org | I14: Banque mondiale | J14: BM | K14: AGRICULTURE | L14: Don | M14: 0 | N14: 8400000000 | O14: 8400000000 | P14: DTS | Q14: 11000000 | R14: Don | S14: 40701 | T14: 40626 | U14: 42735 | V14: BORGOU (BEMBÉRÈKÉ(INA)) ; ATLANTIQUE (ALLADA(NIAOULI)) ; OUÉMÉ (ADJOHOUN, BONOU, DANGBO). | Y14: MULTILATERAUX
B15: P-0009-BM-2011 | C15: 2011 | D15: =YEAR(U15) -> 2017 | E15: Projet d'investissement | F15: Projet d'Appui à la Diversification Agricole (PADA) | G15: Restaurer et améliorer la productivité et la compétitivité des filières agricoles cibles (notamment le riz, le maïs, l'anacarde et l'ananas) pour accroître les revenus des petits producteurs et sécuriser la souveraineté alimentaire. | H15: https://banquemondiale.org | I15: Banque mondiale | J15: BM | K15: AGRICULTURE | L15: Don | Prêt | M15: 15500000000 | N15: 7500000000 | O15: 23000000000 | P15: DTS | EUR | Q15: 35000000 | R15: Fonds fiduciaire (Trust Fund) | Prêt concessionnel | S15: 40701 | T15: 40626 | U15: 42794 | V15: OUÉMÉ (DANGBO, ADJOHOUN, BONOU) ; ZOU (ABOMEY, BOHICON, ZAKPOTA) ; COLLINES (DASSA-ZOUMÉ, SAVALOU) ; ATLANTIQUE (ABOMEY-CALAVI, ZÈ). | Y15: MULTILATERAUX
B16: P-0010-BM-2011 | C16: 2011 | D16: =YEAR(U16) -> 2019 | E16: Projet d'investissement | F16: Projet d'Appui à la Gestion des Aires Protégées | G16: Consolider et étendre les investissements destinés à la structuration des chaînes de valeur agricoles afin d'amplifier l'accès aux marchés des groupements de producteurs et d'améliorer la commercialisation des produits locaux. | H16: https://banquemondiale.org | I16: Banque mondiale | J16: BM | K16: CADRE DE VIE | L16: Don | M16: 0 | N16: 3450000000 | O16: 3450000000 | P16: DTS | EUR | Q16: 5200000 | R16: Don | Fonds fiduciaire (Trust Fund) | S16: 40701 | T16: 40631 | U16: 43646 | V16: OUÉMÉ (DANGBO, ADJOHOUN, BONOU) ; ZOU (ABOMEY, BOHICON, ZAKPOTA) ; COLLINES (DASSA-ZOUMÉ, SAVALOU) ; ATLANTIQUE (ABOMEY-CALAVI, ZÈ). | Y16: MULTILATERAUX
B17: P-0011-BM-2011 | C17: 2011 | D17: =YEAR(U17) -> 2019 | E17: Projet d'investissement | F17: Projet d'Urgence de Gestion Environnementale en Milieu Urbain | G17: Améliorer la gestion durable des écosystèmes des parcs nationaux du W et de la Pendjari, renforcer la conservation de la biodiversité et impliquer les communautés locales dans la gouvernance des ressources naturelles. | H17: https://banquemondiale.org | I17: Banque mondiale | J17: BM | K17: CADRE DE VIE | L17: Prêt | M17: 25000000000 | N17: 0 | O17: 25000000000 | P17: DTS | Q17: 31600000 | R17: Prêt concessionnel | S17: 40701 | T17: 40631 | U17: 43496 | V17: ATACORA (TANGUIÉTA(TANGUIÉTA CENTRE), KÉROU) ; ALIBORI (BANIKOARA(BANIKOARA CENTRE)). | Y17: MULTILATERAUX
B18: P-0012-BM-2011 | C18: 2011 | D18: =YEAR(U18) -> 2016 | E18: Projet d'investissement | F18: Projet de Nutrition Communautaire | G18: Réduire la vulnérabilité des populations du Grand Nokoué face aux inondations récurrentes, améliorer les infrastructures d'assainissement pluvial et optimiser la gestion des déchets solides ménagers. | H18: https://evaluation.gouv.bj | I18: Banque mondiale | J18: BM | K18: SANTÉ | L18: Don | M18: 0 | N18: 1398890500 | O18: 1398890500 | P18: EUR | Q18: 2797781 | R18: Don | S18: 40724 | T18: 40687 | U18: 42735 | V18: LITTORAL (COTONOU(DU 1ER AU 13ÈME)) ; ATLANTIQUE (ABOMEY-CALAVI(GODOMEY, ABOMEY-CALAVI CENTRE, AKASSATO), OUIDAH) ; OUÉMÉ (PORTO-NOVO(DU 1ER AU 5ÈME), SÈMÈ-PODJI). | Y18: MULTILATERAUX
B19: P-0013-BOAD-2011 | C19: 2011 | D19: =YEAR(U19) -> 2016 | E19: Projet d'investissement | F19: Projet de pavage de rues et d'assainissement dans la Commune d'Abomey-Calavi | G19: Moderniser la voirie urbaine des arrondissements centraux d'Abomey-Calavi par le pavage et la construction de collecteurs d'eaux pluviales afin d'améliorer les conditions de circulation et d'hygiène des populations. | H19: https://boad.org | I19: Banque Ouest Africaine de Développement | J19: BOAD | K19: CADRE DE VIE | L19: Prêt | M19: 6500000000 | N19: 0 | O19: 6500000000 | P19: XOF | Q19: 6500000000 | R19: Prêt non concessionnel | S19: 40739 | T19: 40688 | U19: 42735 | V19: ATLANTIQUE (ABOMEY-CALAVI(ABOMEY-CALAVI CENTRE, GODOMEY, AKASSATO, ZINVIÉ)). | Y19: MULTILATERAUX
... B89: P-0078-BID-2014 | C89: 2014 | D89: =YEAR(U89) -> 2020 | E89: Projet d'investissement | F89: Projet de Développement de l'Education de Base-Phase IV | G89: Accroître la capacité d'accueil et la mixité du système scolaire par la construction d'infrastructures de collèges ruraux intégrés équipés de blocs sanitaires adaptés. ; Acquérir et distribuer des manuels scolaires et des guides didactiques et renforcer la formation pédagogique continue des instituteurs et enseignants contractuels. | H89: documentation-anbenin.org | I89: Banque Islamique de Développement | J89: BID | K89: ÉDUCATION | L89: Prêt | M89: 6080000000 | N89: 0 | O89: 6080000000 | P89: DI | EUR | Q89: 9670000 | R89: Istisna'a | S89: 41802 | T89: 41800 | U89: 44012 | V89: NATIONAL | Y89: MULTILATERAUX
B90: P-0079-BID-2014 | C90: 2014 | D90: =YEAR(U90) -> 2018 | E90: Projet d'investissement | F90: Projet BID-UEMOA d'hydraulique et d'assainissement en milieu rural | G90: Approvisionner durablement en eau potable les localités rurales cibles des départements du Bénin à travers la réalisation de forages équipés de pompes manuelles ou solaires. | H90: documentation-anbenin.org | I90: Banque Islamique de Développement | J90: BID | K90: EAU ET ASSAINISSEMENT | L90: Prêt | M90: 6250000000 | N90: 0 | O90: 6250000000 | P90: EUR | Q90: 12500000 | R90: Istisna'a | S90: 41816 | T90: 41690 | U90: 43465 | V90: ATACORA ; DONGA ; BORGOU ; ALIBORI ; ZOU ; COLLINES. | W90: APD | X90: PRÊT | Y90: MULTILATERAUX | Z90: ACCÈS À L’EAU POTABLE | AA90: AXE 6 | AB90: PILIER 3 | AC90: ODD 6 | AD90: 6.1 | AE90: Environnemental | AF90: en cours
B91: P-0080-UEMOA-2014 | C91: 2014 | D91: =YEAR(U91) -> 2018 | E91: Projet d'investissement | F91: Bonification du taux d'intérêt du prêt relatif au financement partiel du Projet de renforcement du système d'alimentation en eau potable dans 69 villages | G91: Réduire le coût financier global de la dette contractée pour les infrastructures d'adduction d'eau villageoise au profit de la viabilité budgétaire du programme. | H91: documentation-anbenin.org | I91: Union Économique et Monétaire Ouest Africaine | J91: UEMOA | K91: EAU ET ASSAINISSEMENT | L91: Don | M91: 0 | N91: 1124584425 | O91: 1124584425 | P91: XOF | Q91: 1124584425 | R91: Don | S91: 41815 | T91: 41774 | U91: 43465 | V91: NATIONAL | Y91: MULTILATERAUX
B92: P-0081-AFD-2014 | C92: 2014 | D92: =YEAR(U92) -> 2018 | E92: Projet d'investissement | F92: Projet d'appui au renforcement des acteurs du secteur privé | G92: Mettre en œuvre des programmes d'appui à la mise à niveau des entreprises industrielles locales et faciliter leur accès aux financements de trésorerie et d'investissement. | H92: evaluation.gouv.bj | I92: Agence Française de Développement | J92: AFD | K92: PROTECTION SOCIALE ET EMPLOI | L92: Don | M92: 0 | N92: 682195280 | O92: 682195280 | P92: EUR | Q92: 1040090.4 | R92: Don | S92: 41922 | T92: 41856 | U92: 43465 | V92: NATIONAL | Y92: BILATERAUX
